2018-03-19 14:02:39,992 (2959/MainThread) pgcli.main INFO - Default pager found in PAGER environment variable: "less"
2018-03-19 14:03:07,717 (2959/MainThread) pgcli.pgexecute ERROR - sql: u'select * from commerce_product', error: ProgrammingError('relation "commerce_product" does not exist\nLINE 1: select * from commerce_product\n                      ^\n',)
2018-03-19 14:03:07,717 (2959/MainThread) pgcli.pgexecute ERROR - traceback: 'Traceback (most recent call last):\n  File "/usr/local/Cellar/pgcli/1.9.0/libexec/lib/python2.7/site-packages/pgcli/pgexecute.py", line 319, in run\n    yield self.execute_normal_sql(sql) + (sql, True)\n  File "/usr/local/Cellar/pgcli/1.9.0/libexec/lib/python2.7/site-packages/pgcli/pgexecute.py", line 355, in execute_normal_sql\n    cur.execute(split_sql)\nProgrammingError: relation "commerce_product" does not exist\nLINE 1: select * from commerce_product\n                      ^\n\n'
2018-03-19 14:03:39,388 (2978/MainThread) pgcli.main INFO - Default pager found in PAGER environment variable: "less"
2018-03-19 14:08:58,476 (2978/MainThread) pgcli.pgexecute ERROR - sql: u'select\n    code, name, trays', error: ProgrammingError('column "code" does not exist\nLINE 2:     code, name, trays\n            ^\n',)
2018-03-19 14:08:58,476 (2978/MainThread) pgcli.pgexecute ERROR - traceback: 'Traceback (most recent call last):\n  File "/usr/local/Cellar/pgcli/1.9.0/libexec/lib/python2.7/site-packages/pgcli/pgexecute.py", line 319, in run\n    yield self.execute_normal_sql(sql) + (sql, True)\n  File "/usr/local/Cellar/pgcli/1.9.0/libexec/lib/python2.7/site-packages/pgcli/pgexecute.py", line 355, in execute_normal_sql\n    cur.execute(split_sql)\nProgrammingError: column "code" does not exist\nLINE 2:     code, name, trays\n            ^\n\n'
2018-03-19 14:10:19,149 (2978/MainThread) pgcli.pgexecute ERROR - sql: u"select\n    code, name, trays, includes\nfrom    \n    commerce_product\nwhere code like 'impr%'", error: ProgrammingError('column "includes" does not exist\nLINE 2:     code, name, trays, includes\n                               ^\n',)
2018-03-19 14:10:19,149 (2978/MainThread) pgcli.pgexecute ERROR - traceback: 'Traceback (most recent call last):\n  File "/usr/local/Cellar/pgcli/1.9.0/libexec/lib/python2.7/site-packages/pgcli/pgexecute.py", line 319, in run\n    yield self.execute_normal_sql(sql) + (sql, True)\n  File "/usr/local/Cellar/pgcli/1.9.0/libexec/lib/python2.7/site-packages/pgcli/pgexecute.py", line 355, in execute_normal_sql\n    cur.execute(split_sql)\nProgrammingError: column "includes" does not exist\nLINE 2:     code, name, trays, includes\n                               ^\n\n'
2018-03-20 12:25:08,835 (2978/MainThread) pgcli.pgexecute ERROR - sql: u'select id, filename from pyrunner_script', error: ProgrammingError('column "filename" does not exist\nLINE 1: select id, filename from pyrunner_script\n                   ^\n',)
2018-03-20 12:25:08,839 (2978/MainThread) pgcli.pgexecute ERROR - traceback: 'Traceback (most recent call last):\n  File "/usr/local/Cellar/pgcli/1.9.0/libexec/lib/python2.7/site-packages/pgcli/pgexecute.py", line 319, in run\n    yield self.execute_normal_sql(sql) + (sql, True)\n  File "/usr/local/Cellar/pgcli/1.9.0/libexec/lib/python2.7/site-packages/pgcli/pgexecute.py", line 355, in execute_normal_sql\n    cur.execute(split_sql)\nProgrammingError: column "filename" does not exist\nLINE 1: select id, filename from pyrunner_script\n                   ^\n\n'
2018-03-20 12:25:13,940 (2978/MainThread) pgcli.pgexecute ERROR - sql: u'select id, filename from pyrunner_script', error: ProgrammingError('column "filename" does not exist\nLINE 1: select id, filename from pyrunner_script\n                   ^\n',)
2018-03-20 12:25:13,940 (2978/MainThread) pgcli.pgexecute ERROR - traceback: 'Traceback (most recent call last):\n  File "/usr/local/Cellar/pgcli/1.9.0/libexec/lib/python2.7/site-packages/pgcli/pgexecute.py", line 319, in run\n    yield self.execute_normal_sql(sql) + (sql, True)\n  File "/usr/local/Cellar/pgcli/1.9.0/libexec/lib/python2.7/site-packages/pgcli/pgexecute.py", line 355, in execute_normal_sql\n    cur.execute(split_sql)\nProgrammingError: column "filename" does not exist\nLINE 1: select id, filename from pyrunner_script\n                   ^\n\n'
2018-03-20 12:26:17,908 (2978/MainThread) pgcli.pgexecute ERROR - sql: u'delete from pyrunner_script wher id >= 237', error: ProgrammingError('syntax error at or near "id"\nLINE 1: delete from pyrunner_script wher id >= 237\n                                         ^\n',)
2018-03-20 12:26:17,909 (2978/MainThread) pgcli.pgexecute ERROR - traceback: 'Traceback (most recent call last):\n  File "/usr/local/Cellar/pgcli/1.9.0/libexec/lib/python2.7/site-packages/pgcli/pgexecute.py", line 319, in run\n    yield self.execute_normal_sql(sql) + (sql, True)\n  File "/usr/local/Cellar/pgcli/1.9.0/libexec/lib/python2.7/site-packages/pgcli/pgexecute.py", line 355, in execute_normal_sql\n    cur.execute(split_sql)\nProgrammingError: syntax error at or near "id"\nLINE 1: delete from pyrunner_script wher id >= 237\n                                         ^\n\n'
2018-03-21 12:08:35,195 (2978/MainThread) pgcli.pgexecute ERROR - sql: u'select * from order_item where product_id = 559', error: ProgrammingError('relation "order_item" does not exist\nLINE 1: select * from order_item where product_id = 559\n                      ^\n',)
2018-03-21 12:08:35,196 (2978/MainThread) pgcli.pgexecute ERROR - traceback: 'Traceback (most recent call last):\n  File "/usr/local/Cellar/pgcli/1.9.0/libexec/lib/python2.7/site-packages/pgcli/pgexecute.py", line 319, in run\n    yield self.execute_normal_sql(sql) + (sql, True)\n  File "/usr/local/Cellar/pgcli/1.9.0/libexec/lib/python2.7/site-packages/pgcli/pgexecute.py", line 355, in execute_normal_sql\n    cur.execute(split_sql)\nProgrammingError: relation "order_item" does not exist\nLINE 1: select * from order_item where product_id = 559\n                      ^\n\n'
2018-03-21 12:12:20,098 (2978/MainThread) pgcli.pgexecute ERROR - sql: u'exit()', error: ProgrammingError('syntax error at or near "exit"\nLINE 1: exit()\n        ^\n',)
2018-03-21 12:12:20,099 (2978/MainThread) pgcli.pgexecute ERROR - traceback: 'Traceback (most recent call last):\n  File "/usr/local/Cellar/pgcli/1.9.0/libexec/lib/python2.7/site-packages/pgcli/pgexecute.py", line 319, in run\n    yield self.execute_normal_sql(sql) + (sql, True)\n  File "/usr/local/Cellar/pgcli/1.9.0/libexec/lib/python2.7/site-packages/pgcli/pgexecute.py", line 355, in execute_normal_sql\n    cur.execute(split_sql)\nProgrammingError: syntax error at or near "exit"\nLINE 1: exit()\n        ^\n\n'
2018-03-21 12:13:01,207 (12220/MainThread) pgcli.main INFO - Default pager found in PAGER environment variable: "less"
2018-03-21 12:14:51,402 (12328/MainThread) pgcli.main INFO - Default pager found in PAGER environment variable: "less"
2018-03-21 12:17:33,762 (12328/MainThread) pgcli.pgexecute ERROR - sql: u'select * from products order by id desc limit 10', error: ProgrammingError('relation "products" does not exist\nLINE 1: select * from products order by id desc limit 10\n                      ^\n',)
2018-03-21 12:17:33,766 (12328/MainThread) pgcli.pgexecute ERROR - traceback: 'Traceback (most recent call last):\n  File "/usr/local/Cellar/pgcli/1.9.0/libexec/lib/python2.7/site-packages/pgcli/pgexecute.py", line 319, in run\n    yield self.execute_normal_sql(sql) + (sql, True)\n  File "/usr/local/Cellar/pgcli/1.9.0/libexec/lib/python2.7/site-packages/pgcli/pgexecute.py", line 355, in execute_normal_sql\n    cur.execute(split_sql)\nProgrammingError: relation "products" does not exist\nLINE 1: select * from products order by id desc limit 10\n                      ^\n\n'
2018-03-21 12:19:06,946 (12397/MainThread) pgcli.main INFO - Default pager found in PAGER environment variable: "less"
2018-03-21 16:27:32,513 (12397/MainThread) pgcli.pgexecute ERROR - sql: u'select kind from commerce_order\n', error: ProgrammingError('column "kind" does not exist\nLINE 1: select kind from commerce_order\n               ^\n',)
2018-03-21 16:27:32,514 (12397/MainThread) pgcli.pgexecute ERROR - traceback: 'Traceback (most recent call last):\n  File "/usr/local/Cellar/pgcli/1.9.0/libexec/lib/python2.7/site-packages/pgcli/pgexecute.py", line 319, in run\n    yield self.execute_normal_sql(sql) + (sql, True)\n  File "/usr/local/Cellar/pgcli/1.9.0/libexec/lib/python2.7/site-packages/pgcli/pgexecute.py", line 355, in execute_normal_sql\n    cur.execute(split_sql)\nProgrammingError: column "kind" does not exist\nLINE 1: select kind from commerce_order\n               ^\n\n'
2018-03-21 16:32:08,005 (12397/MainThread) pgcli.pgexecute ERROR - sql: u'select order_kind from commerce_order\nlimit 10 order by id desc', error: ProgrammingError('syntax error at or near "order"\nLINE 2: limit 10 order by id desc\n                 ^\n',)
2018-03-21 16:32:08,009 (12397/MainThread) pgcli.pgexecute ERROR - traceback: 'Traceback (most recent call last):\n  File "/usr/local/Cellar/pgcli/1.9.0/libexec/lib/python2.7/site-packages/pgcli/pgexecute.py", line 319, in run\n    yield self.execute_normal_sql(sql) + (sql, True)\n  File "/usr/local/Cellar/pgcli/1.9.0/libexec/lib/python2.7/site-packages/pgcli/pgexecute.py", line 355, in execute_normal_sql\n    cur.execute(split_sql)\nProgrammingError: syntax error at or near "order"\nLINE 2: limit 10 order by id desc\n                 ^\n\n'
2018-03-22 17:29:24,187 (12397/MainThread) pgcli.pgexecute ERROR - sql: u'selec * from commerce_product', error: ProgrammingError('syntax error at or near "selec"\nLINE 1: selec * from commerce_product\n        ^\n',)
2018-03-22 17:29:24,188 (12397/MainThread) pgcli.pgexecute ERROR - traceback: 'Traceback (most recent call last):\n  File "/usr/local/Cellar/pgcli/1.9.0/libexec/lib/python2.7/site-packages/pgcli/pgexecute.py", line 319, in run\n    yield self.execute_normal_sql(sql) + (sql, True)\n  File "/usr/local/Cellar/pgcli/1.9.0/libexec/lib/python2.7/site-packages/pgcli/pgexecute.py", line 355, in execute_normal_sql\n    cur.execute(split_sql)\nProgrammingError: syntax error at or near "selec"\nLINE 1: selec * from commerce_product\n        ^\n\n'
2018-03-23 13:36:56,067 (12397/MainThread) pgcli.pgexecute ERROR - sql: u'select * from operations_shipment order by id desc limit 10', error: OperationalError('server closed the connection unexpectedly\n\tThis probably means the server terminated abnormally\n\tbefore or while processing the request.\n',)
2018-03-23 13:36:56,070 (12397/MainThread) pgcli.pgexecute ERROR - traceback: 'Traceback (most recent call last):\n  File "/usr/local/Cellar/pgcli/1.9.0/libexec/lib/python2.7/site-packages/pgcli/pgexecute.py", line 319, in run\n    yield self.execute_normal_sql(sql) + (sql, True)\n  File "/usr/local/Cellar/pgcli/1.9.0/libexec/lib/python2.7/site-packages/pgcli/pgexecute.py", line 355, in execute_normal_sql\n    cur.execute(split_sql)\nOperationalError: server closed the connection unexpectedly\n\tThis probably means the server terminated abnormally\n\tbefore or while processing the request.\n\n'
2018-03-23 13:36:56,070 (12397/MainThread) pgcli.main ERROR - sql: u'select * from operations_shipment order by id desc limit 10;', error: OperationalError('server closed the connection unexpectedly\n\tThis probably means the server terminated abnormally\n\tbefore or while processing the request.\n',)
2018-03-23 13:36:56,072 (12397/MainThread) pgcli.main ERROR - traceback: 'Traceback (most recent call last):\n  File "/usr/local/Cellar/pgcli/1.9.0/libexec/lib/python2.7/site-packages/pgcli/main.py", line 459, in execute_command\n    output, query = self._evaluate_command(text)\n  File "/usr/local/Cellar/pgcli/1.9.0/libexec/lib/python2.7/site-packages/pgcli/main.py", line 682, in _evaluate_command\n    for title, cur, headers, status, sql, success in res:\n  File "/usr/local/Cellar/pgcli/1.9.0/libexec/lib/python2.7/site-packages/pgcli/pgexecute.py", line 319, in run\n    yield self.execute_normal_sql(sql) + (sql, True)\n  File "/usr/local/Cellar/pgcli/1.9.0/libexec/lib/python2.7/site-packages/pgcli/pgexecute.py", line 355, in execute_normal_sql\n    cur.execute(split_sql)\nOperationalError: server closed the connection unexpectedly\n\tThis probably means the server terminated abnormally\n\tbefore or while processing the request.\n\n'
2018-03-23 14:47:11,912 (12397/MainThread) pgcli.pgexecute ERROR - sql: u'select os.uuid, coi.number from operations_shipment os\njoin operations_fulfillment ON operations_fulfillment.id = operations_shipment.fulfillment_id\njoin commerce_order_item ON commerce_order_item.id = operations_fulfillment.order_item_id', error: ProgrammingError('invalid reference to FROM-clause entry for table "operations_shipment"\nLINE 2: ...ations_fulfillment ON operations_fulfillment.id = operations...\n                                                             ^\nHINT:  Perhaps you meant to reference the table alias "os".\n',)
2018-03-23 14:47:11,913 (12397/MainThread) pgcli.pgexecute ERROR - traceback: 'Traceback (most recent call last):\n  File "/usr/local/Cellar/pgcli/1.9.0/libexec/lib/python2.7/site-packages/pgcli/pgexecute.py", line 319, in run\n    yield self.execute_normal_sql(sql) + (sql, True)\n  File "/usr/local/Cellar/pgcli/1.9.0/libexec/lib/python2.7/site-packages/pgcli/pgexecute.py", line 355, in execute_normal_sql\n    cur.execute(split_sql)\nProgrammingError: invalid reference to FROM-clause entry for table "operations_shipment"\nLINE 2: ...ations_fulfillment ON operations_fulfillment.id = operations...\n                                                             ^\nHINT:  Perhaps you meant to reference the table alias "os".\n\n'
2018-03-23 14:47:31,800 (12397/MainThread) pgcli.pgexecute ERROR - sql: u'select os.uuid, coi.number from operations_shipment os\njoin operations_fulfillment ON operations_fulfillment.id = os.fulfillment_id\njoin commerce_order_item ON commerce_order_item.id = operations_fulfillment.order_item_id', error: ProgrammingError('missing FROM-clause entry for table "coi"\nLINE 1: select os.uuid, coi.number from operations_shipment os\n                        ^\n',)
2018-03-23 14:47:31,801 (12397/MainThread) pgcli.pgexecute ERROR - traceback: 'Traceback (most recent call last):\n  File "/usr/local/Cellar/pgcli/1.9.0/libexec/lib/python2.7/site-packages/pgcli/pgexecute.py", line 319, in run\n    yield self.execute_normal_sql(sql) + (sql, True)\n  File "/usr/local/Cellar/pgcli/1.9.0/libexec/lib/python2.7/site-packages/pgcli/pgexecute.py", line 355, in execute_normal_sql\n    cur.execute(split_sql)\nProgrammingError: missing FROM-clause entry for table "coi"\nLINE 1: select os.uuid, coi.number from operations_shipment os\n                        ^\n\n'
2018-03-23 14:47:57,917 (12397/MainThread) pgcli.pgexecute ERROR - sql: u'select os.uuid, coi.number from operations_shipment os\njoin operations_fulfillment ON operations_fulfillment.id = os.fulfillment_id\njoin commerce_order_item coi ON oi.id = operations_fulfillment.order_item_id', error: ProgrammingError('missing FROM-clause entry for table "oi"\nLINE 3: join commerce_order_item coi ON oi.id = operations_fulfillme...\n                                        ^\n',)
2018-03-23 14:47:57,917 (12397/MainThread) pgcli.pgexecute ERROR - traceback: 'Traceback (most recent call last):\n  File "/usr/local/Cellar/pgcli/1.9.0/libexec/lib/python2.7/site-packages/pgcli/pgexecute.py", line 319, in run\n    yield self.execute_normal_sql(sql) + (sql, True)\n  File "/usr/local/Cellar/pgcli/1.9.0/libexec/lib/python2.7/site-packages/pgcli/pgexecute.py", line 355, in execute_normal_sql\n    cur.execute(split_sql)\nProgrammingError: missing FROM-clause entry for table "oi"\nLINE 3: join commerce_order_item coi ON oi.id = operations_fulfillme...\n                                        ^\n\n'
2018-03-23 14:48:16,888 (12397/MainThread) pgcli.pgexecute ERROR - sql: u'select os.uuid, coi.number from operations_shipment os\njoin operations_fulfillment ON operations_fulfillment.id = os.fulfillment_id\njoin commerce_order_item coi ON coi.id = operations_fulfillment.order_item_id', error: ProgrammingError('column coi.number does not exist\nLINE 1: select os.uuid, coi.number from operations_shipment os\n                        ^\n',)
2018-03-23 14:48:16,888 (12397/MainThread) pgcli.pgexecute ERROR - traceback: 'Traceback (most recent call last):\n  File "/usr/local/Cellar/pgcli/1.9.0/libexec/lib/python2.7/site-packages/pgcli/pgexecute.py", line 319, in run\n    yield self.execute_normal_sql(sql) + (sql, True)\n  File "/usr/local/Cellar/pgcli/1.9.0/libexec/lib/python2.7/site-packages/pgcli/pgexecute.py", line 355, in execute_normal_sql\n    cur.execute(split_sql)\nProgrammingError: column coi.number does not exist\nLINE 1: select os.uuid, coi.number from operations_shipment os\n                        ^\n\n'
2018-03-23 14:53:28,879 (12397/MainThread) pgcli.pgexecute ERROR - sql: u'select os.uuid, co.number from operations_shipment os\njoin operations_fulfillment ON operations_fulfillment.id = os.fulfillment_id\njoin commerce_order_item coi ON coi.id = operations_fulfillment.order_item_id\njoin commerce_order co ON commerce_order.id = coi.order_id', error: ProgrammingError('invalid reference to FROM-clause entry for table "commerce_order"\nLINE 4: join commerce_order co ON commerce_order.id = coi.order_id\n                                  ^\nHINT:  Perhaps you meant to reference the table alias "co".\n',)
2018-03-23 14:53:28,880 (12397/MainThread) pgcli.pgexecute ERROR - traceback: 'Traceback (most recent call last):\n  File "/usr/local/Cellar/pgcli/1.9.0/libexec/lib/python2.7/site-packages/pgcli/pgexecute.py", line 319, in run\n    yield self.execute_normal_sql(sql) + (sql, True)\n  File "/usr/local/Cellar/pgcli/1.9.0/libexec/lib/python2.7/site-packages/pgcli/pgexecute.py", line 355, in execute_normal_sql\n    cur.execute(split_sql)\nProgrammingError: invalid reference to FROM-clause entry for table "commerce_order"\nLINE 4: join commerce_order co ON commerce_order.id = coi.order_id\n                                  ^\nHINT:  Perhaps you meant to reference the table alias "co".\n\n'
2018-03-23 15:19:12,410 (12397/MainThread) pgcli.pgexecute ERROR - sql: u"delete * from cases_case_event_log where event_id = 'PUTTYPURCH'\n", error: ProgrammingError('syntax error at or near "*"\nLINE 1: delete * from cases_case_event_log where event_id = \'PUTTYPU...\n               ^\n',)
2018-03-23 15:19:12,411 (12397/MainThread) pgcli.pgexecute ERROR - traceback: 'Traceback (most recent call last):\n  File "/usr/local/Cellar/pgcli/1.9.0/libexec/lib/python2.7/site-packages/pgcli/pgexecute.py", line 319, in run\n    yield self.execute_normal_sql(sql) + (sql, True)\n  File "/usr/local/Cellar/pgcli/1.9.0/libexec/lib/python2.7/site-packages/pgcli/pgexecute.py", line 355, in execute_normal_sql\n    cur.execute(split_sql)\nProgrammingError: syntax error at or near "*"\nLINE 1: delete * from cases_case_event_log where event_id = \'PUTTYPU...\n               ^\n\n'
